[2024-03-01T15:07:38.392-0500] {taskinstance.py:1159} INFO - Dependencies all met for dep_context=non-requeueable deps ti=<TaskInstance: etl_customer_dag.upload_to_s3 manual__2024-03-01T20:07:28.909150+00:00 [queued]>
[2024-03-01T15:07:38.442-0500] {taskinstance.py:1159} INFO - Dependencies all met for dep_context=requeueable deps ti=<TaskInstance: etl_customer_dag.upload_to_s3 manual__2024-03-01T20:07:28.909150+00:00 [queued]>
[2024-03-01T15:07:38.442-0500] {taskinstance.py:1361} INFO - Starting attempt 1 of 1
[2024-03-01T15:07:38.452-0500] {taskinstance.py:1382} INFO - Executing <Task(PythonOperator): upload_to_s3> on 2024-03-01 20:07:28.909150+00:00
[2024-03-01T15:07:38.456-0500] {standard_task_runner.py:57} INFO - Started process 52922 to run task
[2024-03-01T15:07:38.460-0500] {standard_task_runner.py:84} INFO - Running: ['airflow', 'tasks', 'run', 'etl_customer_dag', 'upload_to_s3', 'manual__2024-03-01T20:07:28.909150+00:00', '--job-id', '131', '--raw', '--subdir', 'DAGS_FOLDER/etl_customer_dag.py', '--cfg-path', '/var/folders/0j/ct19m_4d33qfzqs3tkf7s7rm0000gq/T/tmpsodzwq57']
[2024-03-01T15:07:38.463-0500] {standard_task_runner.py:85} INFO - Job 131: Subtask upload_to_s3
[2024-03-01T15:07:38.556-0500] {task_command.py:416} INFO - Running <TaskInstance: etl_customer_dag.upload_to_s3 manual__2024-03-01T20:07:28.909150+00:00 [running]> on host venkatasaismbp.hsd1.nj.comcast.net
[2024-03-01T15:07:38.691-0500] {taskinstance.py:1662} INFO - Exporting env vars: AIRFLOW_CTX_DAG_OWNER='Venkata' AIRFLOW_CTX_DAG_ID='etl_customer_dag' AIRFLOW_CTX_TASK_ID='upload_to_s3' AIRFLOW_CTX_EXECUTION_DATE='2024-03-01T20:07:28.909150+00:00' AIRFLOW_CTX_TRY_NUMBER='1' AIRFLOW_CTX_DAG_RUN_ID='manual__2024-03-01T20:07:28.909150+00:00'
[2024-03-01T15:07:38.712-0500] {base.py:73} INFO - Using connection ID 'aws_conn_s3' for task execution.
[2024-03-01T15:07:38.713-0500] {connection_wrapper.py:382} INFO - AWS Connection (conn_id='aws_conn_s3', conn_type='aws') credentials retrieved from login and ***.
[2024-03-01T15:11:22.666-0500] {local_task_job_runner.py:294} WARNING - State of this instance has been externally set to failed. Terminating instance.
[2024-03-01T15:11:22.685-0500] {process_utils.py:131} INFO - Sending 15 to group 52922. PIDs of all processes in the group: [52922]
[2024-03-01T15:11:22.686-0500] {process_utils.py:86} INFO - Sending the signal 15 to group 52922
[2024-03-01T15:12:22.707-0500] {process_utils.py:149} WARNING - process psutil.Process(pid=52922, name='Python', status='running', started='15:07:38') did not respond to SIGTERM. Trying SIGKILL
[2024-03-01T15:12:22.712-0500] {process_utils.py:86} INFO - Sending the signal 9 to group 52922
[2024-03-01T15:12:22.726-0500] {process_utils.py:79} INFO - Process psutil.Process(pid=52922, name='Python', status='terminated', exitcode=<Negsignal.SIGKILL: -9>, started='15:07:38') (52922) terminated with exit code -9
[2024-03-01T15:12:22.728-0500] {standard_task_runner.py:172} ERROR - Job 131 was killed before it finished (likely due to running out of memory)
