[2024-02-26T10:31:16.643-0500] {taskinstance.py:1159} INFO - Dependencies all met for dep_context=non-requeueable deps ti=<TaskInstance: s3_to_postgres.read_s3_file_task scheduled__2024-02-26T00:00:00+00:00 [queued]>
[2024-02-26T10:31:16.651-0500] {taskinstance.py:1159} INFO - Dependencies all met for dep_context=requeueable deps ti=<TaskInstance: s3_to_postgres.read_s3_file_task scheduled__2024-02-26T00:00:00+00:00 [queued]>
[2024-02-26T10:31:16.651-0500] {taskinstance.py:1361} INFO - Starting attempt 1 of 1
[2024-02-26T10:31:16.664-0500] {taskinstance.py:1382} INFO - Executing <Task(PythonOperator): read_s3_file_task> on 2024-02-26 00:00:00+00:00
[2024-02-26T10:31:16.669-0500] {standard_task_runner.py:57} INFO - Started process 11047 to run task
[2024-02-26T10:31:16.677-0500] {standard_task_runner.py:84} INFO - Running: ['airflow', 'tasks', 'run', 's3_to_postgres', 'read_s3_file_task', 'scheduled__2024-02-26T00:00:00+00:00', '--job-id', '18', '--raw', '--subdir', 'DAGS_FOLDER/S3_to_postgres.py', '--cfg-path', '/var/folders/0j/ct19m_4d33qfzqs3tkf7s7rm0000gq/T/tmpf44o567j']
[2024-02-26T10:31:16.681-0500] {standard_task_runner.py:85} INFO - Job 18: Subtask read_s3_file_task
[2024-02-26T10:31:16.777-0500] {task_command.py:416} INFO - Running <TaskInstance: s3_to_postgres.read_s3_file_task scheduled__2024-02-26T00:00:00+00:00 [running]> on host venkatasaismbp.hsd1.nj.comcast.net
[2024-02-26T10:31:16.901-0500] {taskinstance.py:1662} INFO - Exporting env vars: AIRFLOW_CTX_DAG_OWNER='Venkata' AIRFLOW_CTX_DAG_ID='s3_to_postgres' AIRFLOW_CTX_TASK_ID='read_s3_file_task' AIRFLOW_CTX_EXECUTION_DATE='2024-02-26T00:00:00+00:00' AIRFLOW_CTX_TRY_NUMBER='1' AIRFLOW_CTX_DAG_RUN_ID='scheduled__2024-02-26T00:00:00+00:00'
[2024-02-26T10:31:16.924-0500] {base_aws.py:581} WARNING - Unable to find AWS Connection ID 'aws_conn_s3', switching to empty.
[2024-02-26T10:31:16.925-0500] {base_aws.py:161} INFO - No connection ID provided. Fallback on boto3 credential strategy (region_name=None). See: https://boto3.amazonaws.com/v1/documentation/api/latest/guide/configuration.html
[2024-02-26T10:48:58.235-0500] {local_task_job_runner.py:294} WARNING - State of this instance has been externally set to failed. Terminating instance.
[2024-02-26T10:48:58.249-0500] {process_utils.py:131} INFO - Sending 15 to group 11047. PIDs of all processes in the group: [11047]
[2024-02-26T10:48:58.250-0500] {process_utils.py:86} INFO - Sending the signal 15 to group 11047
[2024-02-26T11:01:26.675-0500] {process_utils.py:149} WARNING - process psutil.Process(pid=11047, name='Python', status='running', started='10:31:16') did not respond to SIGTERM. Trying SIGKILL
[2024-02-26T11:01:26.679-0500] {process_utils.py:86} INFO - Sending the signal 9 to group 11047
[2024-02-26T11:01:26.687-0500] {process_utils.py:79} INFO - Process psutil.Process(pid=11047, name='Python', status='terminated', exitcode=<Negsignal.SIGKILL: -9>, started='10:31:16') (11047) terminated with exit code -9
[2024-02-26T11:01:26.688-0500] {standard_task_runner.py:172} ERROR - Job 18 was killed before it finished (likely due to running out of memory)
